2024-03-25 07:56:58,945:INFO:CSV file has read successfully from the below pathC:\Users\A4952\PycharmProjects\Data_Automation_project\source_files\Contact_info.csv
2024-03-25 07:56:58,968:INFO:CSV file has read successfully from the below pathC:\Users\A4952\PycharmProjects\Data_Automation_project\source_files\Contact_info_t.csv
2024-03-25 07:57:01,728:INFO:Error while receiving.
Traceback (most recent call last):
  File "C:\Users\A4952\Downloads\spark-3.3.4-bin-hadoop3\spark-3.3.4-bin-hadoop3\python\lib\py4j-0.10.9.5-src.zip\py4j\clientserver.py", line 511, in send_command
    answer = smart_decode(self.stream.readline()[:-1])
RuntimeError: reentrant call inside <_io.BufferedReader name=1672>
2024-03-25 07:57:01,729:INFO:Closing down clientserver connection
2024-03-25 07:57:01,729:ERROR:Exception while sending command.
Traceback (most recent call last):
  File "C:\Users\A4952\Downloads\spark-3.3.4-bin-hadoop3\spark-3.3.4-bin-hadoop3\python\lib\py4j-0.10.9.5-src.zip\py4j\clientserver.py", line 511, in send_command
    answer = smart_decode(self.stream.readline()[:-1])
RuntimeError: reentrant call inside <_io.BufferedReader name=1672>

During handling of the above exception, another exception occurred:

Traceback (most recent call last):
  File "C:\Users\A4952\Downloads\spark-3.3.4-bin-hadoop3\spark-3.3.4-bin-hadoop3\python\lib\py4j-0.10.9.5-src.zip\py4j\java_gateway.py", line 1038, in send_command
    response = connection.send_command(command)
  File "C:\Users\A4952\Downloads\spark-3.3.4-bin-hadoop3\spark-3.3.4-bin-hadoop3\python\lib\py4j-0.10.9.5-src.zip\py4j\clientserver.py", line 539, in send_command
    raise Py4JNetworkError(
py4j.protocol.Py4JNetworkError: Error while sending or receiving
2024-03-25 07:57:01,731:INFO:Error while receiving.
Traceback (most recent call last):
  File "C:\Users\A4952\Downloads\spark-3.3.4-bin-hadoop3\spark-3.3.4-bin-hadoop3\python\lib\py4j-0.10.9.5-src.zip\py4j\clientserver.py", line 511, in send_command
    answer = smart_decode(self.stream.readline()[:-1])
  File "C:\Users\A4952\AppData\Local\Programs\Python\Python310\lib\socket.py", line 705, in readinto
    return self._sock.recv_into(b)
  File "C:\Users\A4952\Downloads\spark-3.3.4-bin-hadoop3\spark-3.3.4-bin-hadoop3\python\pyspark\context.py", line 362, in signal_handler
    self.cancelAllJobs()
  File "C:\Users\A4952\Downloads\spark-3.3.4-bin-hadoop3\spark-3.3.4-bin-hadoop3\python\pyspark\context.py", line 1447, in cancelAllJobs
    self._jsc.sc().cancelAllJobs()
  File "C:\Users\A4952\Downloads\spark-3.3.4-bin-hadoop3\spark-3.3.4-bin-hadoop3\python\lib\py4j-0.10.9.5-src.zip\py4j\java_gateway.py", line 1321, in __call__
    return_value = get_return_value(
  File "C:\Users\A4952\Downloads\spark-3.3.4-bin-hadoop3\spark-3.3.4-bin-hadoop3\python\pyspark\sql\utils.py", line 190, in deco
    return f(*a, **kw)
  File "C:\Users\A4952\Downloads\spark-3.3.4-bin-hadoop3\spark-3.3.4-bin-hadoop3\python\lib\py4j-0.10.9.5-src.zip\py4j\protocol.py", line 334, in get_return_value
    raise Py4JError(
py4j.protocol.Py4JError: An error occurred while calling o21.sc
2024-03-25 07:57:01,762:INFO:Closing down clientserver connection
2024-03-25 07:57:01,763:ERROR:Exception while sending command.
Traceback (most recent call last):
  File "C:\Users\A4952\Downloads\spark-3.3.4-bin-hadoop3\spark-3.3.4-bin-hadoop3\python\lib\py4j-0.10.9.5-src.zip\py4j\clientserver.py", line 511, in send_command
    answer = smart_decode(self.stream.readline()[:-1])
  File "C:\Users\A4952\AppData\Local\Programs\Python\Python310\lib\socket.py", line 705, in readinto
    return self._sock.recv_into(b)
  File "C:\Users\A4952\Downloads\spark-3.3.4-bin-hadoop3\spark-3.3.4-bin-hadoop3\python\pyspark\context.py", line 362, in signal_handler
    self.cancelAllJobs()
  File "C:\Users\A4952\Downloads\spark-3.3.4-bin-hadoop3\spark-3.3.4-bin-hadoop3\python\pyspark\context.py", line 1447, in cancelAllJobs
    self._jsc.sc().cancelAllJobs()
  File "C:\Users\A4952\Downloads\spark-3.3.4-bin-hadoop3\spark-3.3.4-bin-hadoop3\python\lib\py4j-0.10.9.5-src.zip\py4j\java_gateway.py", line 1321, in __call__
    return_value = get_return_value(
  File "C:\Users\A4952\Downloads\spark-3.3.4-bin-hadoop3\spark-3.3.4-bin-hadoop3\python\pyspark\sql\utils.py", line 190, in deco
    return f(*a, **kw)
  File "C:\Users\A4952\Downloads\spark-3.3.4-bin-hadoop3\spark-3.3.4-bin-hadoop3\python\lib\py4j-0.10.9.5-src.zip\py4j\protocol.py", line 334, in get_return_value
    raise Py4JError(
py4j.protocol.Py4JError: An error occurred while calling o21.sc

During handling of the above exception, another exception occurred:

Traceback (most recent call last):
  File "C:\Users\A4952\Downloads\spark-3.3.4-bin-hadoop3\spark-3.3.4-bin-hadoop3\python\lib\py4j-0.10.9.5-src.zip\py4j\java_gateway.py", line 1038, in send_command
    response = connection.send_command(command)
  File "C:\Users\A4952\Downloads\spark-3.3.4-bin-hadoop3\spark-3.3.4-bin-hadoop3\python\lib\py4j-0.10.9.5-src.zip\py4j\clientserver.py", line 539, in send_command
    raise Py4JNetworkError(
py4j.protocol.Py4JNetworkError: Error while sending or receiving
2024-03-25 07:57:01,763:INFO:Closing down clientserver connection
